#Exception: An error occurred while running the ansible playbook to configure instance. Check the logs. Last output lines were: ['TASK [rke : Install boto3] *****************************************************', 'ok: [35.153.95.183.nip.io]', '', 'TASK [rke : Set aws instance tag] **********************************************', 'fatal: [35.153.95.183.nip.io]: FAILED! => 
d = {"changed": true, "msg": "non-zero return code", "rc": 1, "stderr": "", "stderr_lines": [], "stdout": "Traceback (most recent call last):\\r\\n File \\"/home/ubuntu/.ansible/tmp/ansible-tmp-1665248752.6303225-1073248-253294366171449/set_aws_instance_tag.py\\", line 33, in <module>\\r\\n sys.exit(main(args.cluster_id))\\r\\n File \\"/home/ubuntu/.ansible/tmp/ansible-tmp-1665248752.6303225-1073248-253294366171449/set_aws_instance_tag.py\\", line 22, in main\\r\\n set_instance_tags(region_name, instance_id,\\r\\n File \\"/home/ubuntu/.ansible/tmp/ansible-tmp-1665248752.6303225-1073248-253294366171449/set_aws_instance_tag.py\\", line 13, in set_instance_tags\\r\\n ec2_instance.create_tags(\\r\\n File \\"/home/ubuntu/.local/lib/python3.8/site-packages/boto3/resources/factory.py\\", line 580, in do_action\\r\\n response = action(self, *args, **kwargs)\\r\\n File \\"/home/ubuntu/.local/lib/python3.8/site-packages/boto3/resources/action.py\\", line 88, in __call__\\r\\n response = getattr(parent.meta.client, operation_name)(*args, **params)\\r\\n File \\"/home/ubuntu/.local/lib/python3.8/site-packages/botocore/client.py\\", line 514, in _api_call\\r\\n return self._make_api_call(operation_name, kwargs)\\r\\n File \\"/home/ubuntu/.local/lib/python3.8/site-packages/botocore/client.py\\", line 921, in _make_api_call\\r\\n http, parsed_response = self._make_request(\\r\\n File \\"/home/ubuntu/.local/lib/python3.8/site-packages/botocore/client.py\\", line 944, in _make_request\\r\\n return self._endpoint.make_request(operation_model, request_dict)\\r\\n File \\"/home/ubuntu/.local/lib/python3.8/si
te-packages/botocore/endpoint.py\\", line 119, in make_request\\r\\n return self._send_request(request_dict, operation_model)\\r\\n File \\"/home/ubuntu/.local/lib/python3.8/site-packages/botocore/endpoint.py\\", line 198, in _send_request\\r\\n request = self.create_request(request_dict, operation_model)\\r\\n File \\"/home/ubuntu/.local/lib/python3.8/site-packages/botocore/endpoint.py\\", line 134, in create_request\\r\\n self._event_emitter.emit(\\r\\n File \\"/home/ubuntu/.local/lib/python3.8/site-packages/botocore/hooks.py\\", line 412, in emit\\r\\n return self._emitter.emit(aliased_event_name, **kwargs)\\r\\n File \\"/home/ubuntu/.local/lib/python3.8/site-packages/botocore/hooks.py\\", line 256, in emit\\r\\n return self._emit(event_name, kwargs)\\r\\n File \\"/home/ubuntu/.local/lib/python3.8/site-packages/botocore/hooks.py\\", line 239, in _emit\\r\\n response = handler(**kwargs)\\r\\n File \\"/home/ubuntu/.local/lib/python3.8/site-packages/botocore/signers.py\\", line 105, in handler\\r\\n return self.sign(operation_name, request)\\r\\n File \\"/home/ubuntu/.local/lib/python3.8/site-packages/botocore/signers.py\\", line 189, in sign\\r\\n auth.add_auth(request)\\r\\n File \\"/home/ubuntu/.local/lib/python3.8/site-packages/botocore/auth.py\\", line 418, in add_auth\\r\\n raise NoCredentialsError()\\r\\nbotocore.exceptions.NoCredentialsError: Unable to locate credentials\\r\\n", "stdout_lines": ["Traceback (most recent call last):", " File \\"/home/ubuntu/.ansible/tmp/ansible-tmp-1665248752.6303225-1073248-253294366171449/set_aws_instance_tag.py\\", line 33, in <module>", " sys.exit(main(args.cluster_id))", " File \\"/home/ubuntu/.ansible/tmp/ansible-tmp-1665248752.6303225-1073248-253294366171449/set_aws_instance_tag.py\\", line 22, in main", " set_instance_tags(region_name, instance_id,", " File \\"/home/ubuntu/.ansible/tmp/ansible-tmp-1665248752.6303225-1073248-253294366171449/set_aws_instance_tag.py\\", line 13, in set_instance_tags", " ec2_instance.create
_tags(", " File \\"/home/ubuntu/.local/lib/python3.8/site-packages/boto3/resources/factory.py\\", line 580, in do_action", " response = action(self, *args, **kwargs)", " File \\"/home/ubuntu/.local/lib/python3.8/site-packages/boto3/resources/action.py\\", line 88, in __call__", " response = getattr(parent.meta.client, operation_name)(*args, **params)", " File \\"/home/ubuntu/.local/lib/python3.8/site-packages/botocore/client.py\\", line 514, in _api_call", " return self._make_api_call(operation_name, kwargs)", " File \\"/home/ubuntu/.local/lib/python3.8/site-packages/botocore/client.py\\", line 921, in _make_api_call", " http, parsed_response = self._make_request(", " File \\"/home/ubuntu/.local/lib/python3.8/site-packages/botocore/client.py\\", line 944, in _make_request", " return self._endpoint.make_request(operation_model, request_dict)", " File \\"/home/ubuntu/.local/lib/python3.8/site-packages/botocore/endpoint.py\\", line 119, in make_request", " return self._send_request(request_dict, operation_model)", " File \\"/home/ubuntu/.local/lib/python3.8/site-packages/botocore/endpoint.py\\", line 198, in _send_request", " request = self.create_request(request_dict, operation_model)", " File \\"/home/ubuntu/.local/lib/python3.8/site-packages/botocore/endpoint.py\\", line 134, in create_request", " self._event_emitter.emit(", " File \\"/home/ubuntu/.local/lib/python3.8/site-packages/botocore/hooks.py\\", line 412, in emit", " return self._emitter.emit(aliased_event_name, **kwargs)", " File \\"/home/ubuntu/.local/lib/python3.8/site-packages/botocore/hooks.py\\", line 256, in emit", " return self._emit(event_name, kwargs)", " File \\"/home/ubuntu/.local/lib/python3.8/site-packages/botocore/hooks.py\\", line 239, in _emit", " response = handler(**kwargs)", " File \\"/home/ubuntu/.local/lib/python3.8/site-packages/botocore/signers.py\\", line 105, in handler", " return self.sign(operation_name, request)", " File \\"/home/ubuntu/.local/lib/python3.8/site-packages/botocor
e/signers.py\\", line 189, in sign", " auth.add_auth(request)", " File \\"/home/ubuntu/.local/lib/python3.8/site-packages/botocore/auth.py\\", line 418, in add_auth", " raise NoCredentialsError()", "botocore.exceptions.NoCredentialsError: Unable to locate credentials"]}

from pprint import pprint
pprint(d)

#', '', 'PLAY RECAP *********************************************************************', '35.153.95.183.nip.io : ok=10 changed=0 unreachable=0 failed=1 skipped=0 rescued=0 ignored=0 ', '', '']
